<?xml version="1.0"?>
<robot xmlns:xacro="http://www.ros.org/wiki/xacro" >
    <xacro:include filename="inertial_macros.xacro" />

<!--MATERIAL-->

    <material name="white">
        <color rgba="1 1 1 1" />
    </material>

    <material name="black">
        <color rgba="0 0 0 1"/>
    </material>

<!--PLANE-->

    <link name="plane"></link>

<!--BASEFOOTPRINT-->

    <joint name="footprint_joint" type="fixed">
        <parent link="plane"/>
        <child link="footprint"/>
        <origin xyz="0 0 0" rpy="0 0 0"/>
    </joint>

    <link name="footprint">
    </link>

<!--BODY-->
    
    <joint name="body_joint" type="fixed">
        <parent link="plane"/>
        <child link="body"/>
        <origin xyz="0 0 0"/>
    </joint>

    <link name="body"> 
        <visual> 
            <origin xyz="0 0 0" rpy="0 0 0"/>
            <geometry>
                <mesh filename="file://$(find probobot)/description/body.dae" scale="1 1 1"/> 
            </geometry>
            <material name="white"/>
        </visual>
        <collision> 
            <origin xyz="0 0 0" rpy="0 0 0"/>
            <geometry>
                <mesh filename="file://$(find probobot)/description/body.dae" scale="1 1 1"/>
            </geometry>  
        </collision>
        <xacro:inertial_box mass="50" x="0.7" y="0.7" z="0.2"> 
            <origin xyz="0 0 0.1" rpy="0 0 0"/>
        </xacro:inertial_box>
    </link>

    <gazebo reference="body">
        <material>Gazebo/White</material>
    </gazebo>

<!--LEFTWHEEl-->

    <joint name="left_wheel_joint" type="continuous">
        <parent link="body"/>
        <child link="left_wheel"/>
        <origin xyz="0.4 0.12 0" rpy="0 -${pi/2} 0"/>
        <axis xyz="0 0 -1"/>
    </joint>

    <link name="left_wheel">
        <visual>
            <geometry>
                <cylinder length="0.1" radius="0.15" />
            </geometry>
            <material name="black"/>
        </visual>
        <collision> 
            <geometry>
                <cylinder length="0.1" radius="0.15" />
            </geometry>
        </collision>
        <xacro:inertial_cylinder mass="100" length="0.1" radius="0.15"> 
            <origin xyz="0 0 0" rpy="0 0 ${pi/2}"/>
        </xacro:inertial_cylinder>
    </link>

    <gazebo reference="left_wheel">
        <material>Gazebo/Black</material>
    </gazebo>

<!--RIGHTWHEEl-->

    <joint name="right_wheel_joint" type="continuous">
        <parent link="body"/>
        <child link="right_wheel"/>
        <origin xyz="-0.4 0.12 0" rpy="0 ${pi/2} 0"/>
        <axis xyz="0 0 1"/>
    </joint>

    <link name="right_wheel">
        <visual>
            <geometry>
                <cylinder length="0.1" radius="0.15" />
            </geometry>
            <material name="black"/>
        </visual>
        <collision> 
            <geometry>
                <cylinder length="0.1" radius="0.15" />
            </geometry>
        </collision>
        <xacro:inertial_cylinder mass="100" length="0.1" radius="0.15"> 
            <origin xyz="0 0 0" rpy="0 0 ${pi/2}"/>
        </xacro:inertial_cylinder>
    </link>

    <gazebo reference="right_wheel">
        <material>Gazebo/Black</material>
    </gazebo>

<!--CASTER-->

    <joint name="caster_joint" type="continuous"> 
        <parent link="body"/> 
        <child link="caster_wheel"/> 
        <origin xyz="0 -0.255 0" rpy="0 0 ${pi}"/>
        <axis xyz="0 0 1"/>
    </joint>

    <link name="caster_wheel">
        <visual>
            <geometry>
                <mesh filename="file://$(find probobot)/description/caster.dae" scale="1 1 1"/>
            </geometry>
            <material name="black"/>
        </visual>
        <collision> 
            <geometry>
                <!-- <mesh filename="file://$(find probobot)/description/caster.dae" scale="1 1 1"/> -->
                <cylinder length="0.3" radius="0.075"/>
            </geometry>
        </collision>
        <xacro:inertial_cylinder mass="150" length="0.3" radius="0.075"> 
            <origin xyz="0 0 0" rpy="0 0 ${pi/2}"/>
        </xacro:inertial_cylinder>
    </link>

    <gazebo reference="caster_wheel">
        <material>Gazebo/White</material>
    </gazebo>

<!--SHAFT-->

    <joint name="shaft_joint" type="fixed"> 
        <parent link="body"/> 
        <child link="shaft"/> 
        <origin xyz="0 0 0.3" rpy="0 0 ${pi/2}"/>
        <axis xyz="0 0 1"/>
    </joint>

    <link name="shaft">
        <visual>
            <geometry>
                <cylinder length="0.3" radius="0.05"/>
            </geometry>
            <material name="white"/>
        </visual>
        <collision> 
            <geometry>
                <cylinder length="0.3" radius="0.05"/>
            </geometry>
        </collision>
        <xacro:inertial_cylinder mass="1" length="0.3" radius="0.05"> 
            <origin xyz="0 0 0" rpy="0 0 ${pi/2}"/>
        </xacro:inertial_cylinder>
    </link>

    <gazebo reference="shaft">
        <material>Gazebo/White</material>
    </gazebo>

<!--CRANE-->

    <joint name="crane_joint" type="continuous"> 
        <parent link="shaft"/> 
        <child link="crane"/> 
        <origin xyz="0 0 0.15" rpy="0 0 -${pi/2}"/>
        <axis xyz="0 0 1"/>
        <dynamics damping="1" friction="200" />
    </joint>

    <link name="crane">
        <visual>
            <geometry>
                <mesh filename="file://$(find probobot)/description/crane.dae" scale="1 1 1"/>
            </geometry>
            <material name="white"/>
        </visual>
        <collision> 
            <geometry>
                <mesh filename="file://$(find probobot)/description/crane.dae" scale="1 1 1"/>
            </geometry>
        </collision>
        <xacro:inertial_box mass="10" x="0" y="0" z="0.15"> 
            <origin xyz="0 0 0" rpy="0 0 -${pi/2}"/>
        </xacro:inertial_box>
    </link>

    <gazebo reference="crane">
        <material>Gazebo/White</material>
    </gazebo>

<!--SHAFTY1-->

    <joint name="shafty1_joint" type="prismatic"> 
        <parent link="crane"/> 
        <child link="shafty1"/> 
        <origin xyz="0 0 0.15" rpy="0 0 -${pi/2}"/>
        <axis xyz="1 0 0"/>
        <limit lower="0.6" upper="0.15" effort="100" velocity="0.5"/>
        <dynamics damping="1" friction="50"/>
    </joint>

    <link name="shafty1">
        <visual>
            <geometry>
                <mesh filename="file://$(find probobot)/description/shafty1.dae" scale="1 1 1"/>
            </geometry>
            <material name="white"/>
        </visual>
        <collision> 
            <geometry>
                <mesh filename="file://$(find probobot)/description/shafty1.dae" scale="1 1 1"/>
            </geometry>
        </collision>
        <xacro:inertial_cylinder mass="0.01" length="0.1" radius="0.015"> 
            <origin xyz="0 0 -0.15" rpy="0 0 -${pi/2}"/>
        </xacro:inertial_cylinder>
    </link>

    <gazebo reference="shafty1">
        <material>Gazebo/White</material>
    </gazebo>

<!--SHAFTY2-->

    <joint name="shafty2_joint" type="prismatic"> 
        <parent link="shafty1"/> 
        <child link="shafty2"/> 
        <origin xyz="0 0 0" rpy="0 0 -${pi/2}"/>
        <axis xyz="0 0 -1"/>
        <limit lower="0" upper="0.1" effort="100" velocity="0.5"/>
        <dynamics damping="1" friction="100"/>
    </joint>

    <link name="shafty2">
        <visual>
            <geometry>
                <mesh filename="file://$(find probobot)/description/shafty2.dae" scale="1 1 1"/>
            </geometry>
            <material name="white"/>
        </visual>
        <collision> 
            <geometry>
                <mesh filename="file://$(find probobot)/description/shafty2.dae" scale="1 1 1"/>
            </geometry>
        </collision>
        <xacro:inertial_cylinder mass="0.01" length="0.1" radius="0.01">
            <origin xyz="0 0 -0.1" rpy="0 0 -${pi/2}"/>
        </xacro:inertial_cylinder>
    </link>

    <gazebo reference="shafty2">
        <material>Gazebo/Black</material>
    </gazebo>

<!--SHAFTY3-->

    <joint name="shafty3_joint" type="prismatic"> 
        <parent link="shafty2"/> 
        <child link="shafty3"/> 
        <origin xyz="0 0 0" rpy="0 0 -${pi/2}"/>
        <axis xyz="0 0 -1"/>
        <limit lower="0" upper="0.1" effort="100" velocity="0.5"/>
        <dynamics damping="1" friction="100"/>
    </joint>

    <link name="shafty3">
        <visual>
            <geometry>
                <mesh filename="file://$(find probobot)/description/shafty3.dae" scale="1 1 1"/>
            </geometry>
            <material name="white"/>
        </visual>
        <collision> 
            <geometry>
                <mesh filename="file://$(find probobot)/description/shafty3.dae" scale="1 1 1"/>
            </geometry>
        </collision>
        <xacro:inertial_cylinder mass="0.01" length="0.1" radius="0.005">
            <origin xyz="0 0 0" rpy="0 0 -${pi/2}"/>
        </xacro:inertial_cylinder>
    </link>

    <gazebo reference="shafty3">
        <material>Gazebo/White</material>
    </gazebo>

<!--GAN-->

    <joint name="gan_joint" type="fixed"> 
        <parent link="shafty3"/> 
        <child link="gan"/> 
        <origin xyz="0 0 -0.1" rpy="0 0 0"/>
    </joint>

    <link name="gan">
        <visual>
            <geometry>
                <box size="0.05 0.19 0.04"/>
            </geometry>
            <material name="white"/>
        </visual>
        <collision> 
            <geometry>
                <box size="0.05 0.19 0.04"/>
            </geometry>
        </collision>
        <xacro:inertial_box mass="0.01" x="0.025" y="0.095" z="0.02">
            <origin xyz="0 0 0" rpy="${pi/2} 0 0"/>
        </xacro:inertial_box>
    </link>

    <gazebo reference="gan">
        <material>Gazebo/White</material>
    </gazebo>

<!--GRIP-->

    <joint name="grip_joint" type="revolute"> 
        <parent link="gan"/> 
        <child link="grip"/> 
        <origin xyz="0 -0.085 -0.02" rpy="0 0 0"/>
        <limit lower="-${pi/2}" upper="${pi/18}" effort="10" velocity="10"/>
        <dynamics damping="1" friction="10"/>
    </joint>

    <link name="grip">
        <visual>
            <geometry>
                <mesh filename="file://$(find probobot)/description/grip.dae" scale="1 1 1"/>
            </geometry>
            <material name="white"/>
        </visual>
        <collision> 
            <geometry>
                <mesh filename="file://$(find probobot)/description/grip.dae" scale="1 1 1"/>
            </geometry>
        </collision>
        <xacro:inertial_box mass="0.01" x="0.05" y="0.083" z="0.103">
            <origin xyz="0 0.085 -0.02" rpy="0 0 0"/>
        </xacro:inertial_box>
    </link>

    <gazebo reference="grip">
        <material>Gazebo/Black</material>
    </gazebo>

<!--GRIP-MIMIC-->

    <joint name="grip_joint_mimic" type="revolute"> 
        <parent link="gan"/> 
        <child link="grip_mimic"/>
        <origin xyz="0 0.085 -0.02" rpy="0 0 ${pi}"/>
        <limit lower="-${pi/2}" upper="${pi/18}" effort="10" velocity="10"/>
        <!-- <mimic joint="grip_joint" multiplier="-1.0" offset="0.0" /> -->
        <dynamics damping="1" friction="10"/>
    </joint>

    <link name="grip_mimic">
        <visual>
            <geometry>
                <mesh filename="file://$(find probobot)/description/grip.dae" scale="1 1 1"/>
            </geometry>
            <material name="white"/>
        </visual>
        <collision> 
            <geometry>
                <mesh filename="file://$(find probobot)/description/grip.dae" scale="1 1 1"/>
            </geometry>
        </collision>
        <xacro:inertial_box mass="0.01" x="0.05" y="0.083" z="0.103">
            <origin xyz="0 -0.085 -0.02" rpy="0 0 0"/>
        </xacro:inertial_box>
    </link>

    <gazebo reference="grip_mimic">
        <material>Gazebo/White</material>
    </gazebo>

</robot> 